2020-05-22 14:42:53,466 ERROR: Exception on /user/Susan [GET] [in d:\py\microblog\venv\lib\site-packages\flask\app.py:1890]
Traceback (most recent call last):
  File "d:\py\microblog\venv\lib\site-packages\flask\app.py", line 2446, in wsgi_app
    response = self.full_dispatch_request()
  File "d:\py\microblog\venv\lib\site-packages\flask\app.py", line 1951, in full_dispatch_request
    rv = self.handle_user_exception(e)
  File "d:\py\microblog\venv\lib\site-packages\flask\app.py", line 1820, in handle_user_exception
    reraise(exc_type, exc_value, tb)
  File "d:\py\microblog\venv\lib\site-packages\flask\_compat.py", line 39, in reraise
    raise value
  File "d:\py\microblog\venv\lib\site-packages\flask\app.py", line 1949, in full_dispatch_request
    rv = self.dispatch_request()
  File "d:\py\microblog\venv\lib\site-packages\flask\app.py", line 1935, in dispatch_request
    return self.view_functions[rule.endpoint](**req.view_args)
  File "d:\py\microblog\venv\lib\site-packages\flask_login\utils.py", line 272, in decorated_view
    return func(*args, **kwargs)
  File "D:\py\microblog\app\routes.py", line 67, in user
    posts = current_user.all()
  File "d:\py\microblog\venv\lib\site-packages\werkzeug\local.py", line 347, in __getattr__
    return getattr(self._get_current_object(), name)
AttributeError: 'User' object has no attribute 'all'
2020-05-22 15:03:10,054 INFO: Microblog startup [in D:\py\microblog\app\__init__.py:43]
2020-05-22 15:03:12,793 ERROR: Exception on /user/Susan [GET] [in d:\py\microblog\venv\lib\site-packages\flask\app.py:1890]
Traceback (most recent call last):
  File "d:\py\microblog\venv\lib\site-packages\flask\app.py", line 2446, in wsgi_app
    response = self.full_dispatch_request()
  File "d:\py\microblog\venv\lib\site-packages\flask\app.py", line 1951, in full_dispatch_request
    rv = self.handle_user_exception(e)
  File "d:\py\microblog\venv\lib\site-packages\flask\app.py", line 1820, in handle_user_exception
    reraise(exc_type, exc_value, tb)
  File "d:\py\microblog\venv\lib\site-packages\flask\_compat.py", line 39, in reraise
    raise value
  File "d:\py\microblog\venv\lib\site-packages\flask\app.py", line 1949, in full_dispatch_request
    rv = self.dispatch_request()
  File "d:\py\microblog\venv\lib\site-packages\flask\app.py", line 1935, in dispatch_request
    return self.view_functions[rule.endpoint](**req.view_args)
  File "d:\py\microblog\venv\lib\site-packages\flask_login\utils.py", line 272, in decorated_view
    return func(*args, **kwargs)
  File "D:\py\microblog\app\routes.py", line 67, in user
    posts = current_user.all()
  File "d:\py\microblog\venv\lib\site-packages\werkzeug\local.py", line 347, in __getattr__
    return getattr(self._get_current_object(), name)
AttributeError: 'User' object has no attribute 'all'
2020-05-22 15:03:15,224 ERROR: Exception on /user/Susan [GET] [in d:\py\microblog\venv\lib\site-packages\flask\app.py:1890]
Traceback (most recent call last):
  File "d:\py\microblog\venv\lib\site-packages\flask\app.py", line 2446, in wsgi_app
    response = self.full_dispatch_request()
  File "d:\py\microblog\venv\lib\site-packages\flask\app.py", line 1951, in full_dispatch_request
    rv = self.handle_user_exception(e)
  File "d:\py\microblog\venv\lib\site-packages\flask\app.py", line 1820, in handle_user_exception
    reraise(exc_type, exc_value, tb)
  File "d:\py\microblog\venv\lib\site-packages\flask\_compat.py", line 39, in reraise
    raise value
  File "d:\py\microblog\venv\lib\site-packages\flask\app.py", line 1949, in full_dispatch_request
    rv = self.dispatch_request()
  File "d:\py\microblog\venv\lib\site-packages\flask\app.py", line 1935, in dispatch_request
    return self.view_functions[rule.endpoint](**req.view_args)
  File "d:\py\microblog\venv\lib\site-packages\flask_login\utils.py", line 272, in decorated_view
    return func(*args, **kwargs)
  File "D:\py\microblog\app\routes.py", line 67, in user
    posts = current_user.all()
  File "d:\py\microblog\venv\lib\site-packages\werkzeug\local.py", line 347, in __getattr__
    return getattr(self._get_current_object(), name)
AttributeError: 'User' object has no attribute 'all'
2020-05-22 15:03:38,729 INFO: Microblog startup [in D:\py\microblog\app\__init__.py:43]
2020-05-22 15:04:38,233 INFO: Microblog startup [in D:\py\microblog\app\__init__.py:43]
2020-05-22 15:04:40,746 ERROR: Exception on /user/Susan [GET] [in d:\py\microblog\venv\lib\site-packages\flask\app.py:1890]
Traceback (most recent call last):
  File "d:\py\microblog\venv\lib\site-packages\flask\app.py", line 2446, in wsgi_app
    response = self.full_dispatch_request()
  File "d:\py\microblog\venv\lib\site-packages\flask\app.py", line 1951, in full_dispatch_request
    rv = self.handle_user_exception(e)
  File "d:\py\microblog\venv\lib\site-packages\flask\app.py", line 1820, in handle_user_exception
    reraise(exc_type, exc_value, tb)
  File "d:\py\microblog\venv\lib\site-packages\flask\_compat.py", line 39, in reraise
    raise value
  File "d:\py\microblog\venv\lib\site-packages\flask\app.py", line 1949, in full_dispatch_request
    rv = self.dispatch_request()
  File "d:\py\microblog\venv\lib\site-packages\flask\app.py", line 1935, in dispatch_request
    return self.view_functions[rule.endpoint](**req.view_args)
  File "d:\py\microblog\venv\lib\site-packages\flask_login\utils.py", line 272, in decorated_view
    return func(*args, **kwargs)
  File "D:\py\microblog\app\routes.py", line 69, in user
    posts = Post.query.order_by(Post.timestamp.desc()).current_user.all()
AttributeError: 'BaseQuery' object has no attribute 'current_user'
2020-05-22 15:04:41,518 ERROR: Exception on /user/Susan [GET] [in d:\py\microblog\venv\lib\site-packages\flask\app.py:1890]
Traceback (most recent call last):
  File "d:\py\microblog\venv\lib\site-packages\flask\app.py", line 2446, in wsgi_app
    response = self.full_dispatch_request()
  File "d:\py\microblog\venv\lib\site-packages\flask\app.py", line 1951, in full_dispatch_request
    rv = self.handle_user_exception(e)
  File "d:\py\microblog\venv\lib\site-packages\flask\app.py", line 1820, in handle_user_exception
    reraise(exc_type, exc_value, tb)
  File "d:\py\microblog\venv\lib\site-packages\flask\_compat.py", line 39, in reraise
    raise value
  File "d:\py\microblog\venv\lib\site-packages\flask\app.py", line 1949, in full_dispatch_request
    rv = self.dispatch_request()
  File "d:\py\microblog\venv\lib\site-packages\flask\app.py", line 1935, in dispatch_request
    return self.view_functions[rule.endpoint](**req.view_args)
  File "d:\py\microblog\venv\lib\site-packages\flask_login\utils.py", line 272, in decorated_view
    return func(*args, **kwargs)
  File "D:\py\microblog\app\routes.py", line 69, in user
    posts = Post.query.order_by(Post.timestamp.desc()).current_user.all()
AttributeError: 'BaseQuery' object has no attribute 'current_user'
2020-05-22 15:04:42,058 ERROR: Exception on /user/Susan [GET] [in d:\py\microblog\venv\lib\site-packages\flask\app.py:1890]
Traceback (most recent call last):
  File "d:\py\microblog\venv\lib\site-packages\flask\app.py", line 2446, in wsgi_app
    response = self.full_dispatch_request()
  File "d:\py\microblog\venv\lib\site-packages\flask\app.py", line 1951, in full_dispatch_request
    rv = self.handle_user_exception(e)
  File "d:\py\microblog\venv\lib\site-packages\flask\app.py", line 1820, in handle_user_exception
    reraise(exc_type, exc_value, tb)
  File "d:\py\microblog\venv\lib\site-packages\flask\_compat.py", line 39, in reraise
    raise value
  File "d:\py\microblog\venv\lib\site-packages\flask\app.py", line 1949, in full_dispatch_request
    rv = self.dispatch_request()
  File "d:\py\microblog\venv\lib\site-packages\flask\app.py", line 1935, in dispatch_request
    return self.view_functions[rule.endpoint](**req.view_args)
  File "d:\py\microblog\venv\lib\site-packages\flask_login\utils.py", line 272, in decorated_view
    return func(*args, **kwargs)
  File "D:\py\microblog\app\routes.py", line 69, in user
    posts = Post.query.order_by(Post.timestamp.desc()).current_user.all()
AttributeError: 'BaseQuery' object has no attribute 'current_user'
2020-05-22 15:04:46,014 ERROR: Exception on /user/Susan [GET] [in d:\py\microblog\venv\lib\site-packages\flask\app.py:1890]
Traceback (most recent call last):
  File "d:\py\microblog\venv\lib\site-packages\flask\app.py", line 2446, in wsgi_app
    response = self.full_dispatch_request()
  File "d:\py\microblog\venv\lib\site-packages\flask\app.py", line 1951, in full_dispatch_request
    rv = self.handle_user_exception(e)
  File "d:\py\microblog\venv\lib\site-packages\flask\app.py", line 1820, in handle_user_exception
    reraise(exc_type, exc_value, tb)
  File "d:\py\microblog\venv\lib\site-packages\flask\_compat.py", line 39, in reraise
    raise value
  File "d:\py\microblog\venv\lib\site-packages\flask\app.py", line 1949, in full_dispatch_request
    rv = self.dispatch_request()
  File "d:\py\microblog\venv\lib\site-packages\flask\app.py", line 1935, in dispatch_request
    return self.view_functions[rule.endpoint](**req.view_args)
  File "d:\py\microblog\venv\lib\site-packages\flask_login\utils.py", line 272, in decorated_view
    return func(*args, **kwargs)
  File "D:\py\microblog\app\routes.py", line 69, in user
    posts = Post.query.order_by(Post.timestamp.desc()).current_user.all()
AttributeError: 'BaseQuery' object has no attribute 'current_user'
2020-05-22 15:05:06,052 INFO: Microblog startup [in D:\py\microblog\app\__init__.py:43]
2020-05-22 15:10:01,297 INFO: Microblog startup [in D:\py\microblog\app\__init__.py:43]
