2020-05-10 14:03:53,320 INFO: Microblog startup [in D:\py\microblog\app\__init__.py:43]
2020-05-10 14:30:24,087 INFO: Microblog startup [in D:\py\microblog\app\__init__.py:43]
2020-05-10 14:31:01,693 INFO: Microblog startup [in D:\py\microblog\app\__init__.py:43]
2020-05-10 14:31:19,382 INFO: Microblog startup [in D:\py\microblog\app\__init__.py:43]
2020-05-10 15:40:31,386 INFO: Microblog startup [in D:\py\microblog\app\__init__.py:43]
2020-05-10 15:42:42,486 INFO: Microblog startup [in D:\py\microblog\app\__init__.py:43]
2020-05-10 15:44:22,145 INFO: Microblog startup [in D:\py\microblog\app\__init__.py:43]
2020-05-10 16:03:23,816 INFO: Microblog startup [in D:\py\microblog\app\__init__.py:43]
2020-05-10 16:05:08,882 INFO: Microblog startup [in D:\py\microblog\app\__init__.py:43]
2020-05-10 16:10:01,882 INFO: Microblog startup [in D:\py\microblog\app\__init__.py:43]
2020-05-10 16:10:15,098 ERROR: Exception on /login [POST] [in d:\py\microblog\venv\lib\site-packages\flask\app.py:1890]
Traceback (most recent call last):
  File "d:\py\microblog\venv\lib\site-packages\flask\app.py", line 2446, in wsgi_app
    response = self.full_dispatch_request()
  File "d:\py\microblog\venv\lib\site-packages\flask\app.py", line 1951, in full_dispatch_request
    rv = self.handle_user_exception(e)
  File "d:\py\microblog\venv\lib\site-packages\flask\app.py", line 1820, in handle_user_exception
    reraise(exc_type, exc_value, tb)
  File "d:\py\microblog\venv\lib\site-packages\flask\_compat.py", line 39, in reraise
    raise value
  File "d:\py\microblog\venv\lib\site-packages\flask\app.py", line 1949, in full_dispatch_request
    rv = self.dispatch_request()
  File "d:\py\microblog\venv\lib\site-packages\flask\app.py", line 1935, in dispatch_request
    return self.view_functions[rule.endpoint](**req.view_args)
  File "D:\py\microblog\app\routes.py", line 34, in login
    if user is None or not user.check_password(form.password.data):
  File "D:\py\microblog\app\models.py", line 32, in check_password
    return check_password_hash(self.password_hash, password)
  File "d:\py\microblog\venv\lib\site-packages\werkzeug\security.py", line 218, in check_password_hash
    if pwhash.count("$") < 2:
AttributeError: 'NoneType' object has no attribute 'count'
2020-05-10 16:10:33,806 ERROR: Exception on /login [POST] [in d:\py\microblog\venv\lib\site-packages\flask\app.py:1890]
Traceback (most recent call last):
  File "d:\py\microblog\venv\lib\site-packages\flask\app.py", line 2446, in wsgi_app
    response = self.full_dispatch_request()
  File "d:\py\microblog\venv\lib\site-packages\flask\app.py", line 1951, in full_dispatch_request
    rv = self.handle_user_exception(e)
  File "d:\py\microblog\venv\lib\site-packages\flask\app.py", line 1820, in handle_user_exception
    reraise(exc_type, exc_value, tb)
  File "d:\py\microblog\venv\lib\site-packages\flask\_compat.py", line 39, in reraise
    raise value
  File "d:\py\microblog\venv\lib\site-packages\flask\app.py", line 1949, in full_dispatch_request
    rv = self.dispatch_request()
  File "d:\py\microblog\venv\lib\site-packages\flask\app.py", line 1935, in dispatch_request
    return self.view_functions[rule.endpoint](**req.view_args)
  File "D:\py\microblog\app\routes.py", line 34, in login
    if user is None or not user.check_password(form.password.data):
  File "D:\py\microblog\app\models.py", line 32, in check_password
    return check_password_hash(self.password_hash, password)
  File "d:\py\microblog\venv\lib\site-packages\werkzeug\security.py", line 218, in check_password_hash
    if pwhash.count("$") < 2:
AttributeError: 'NoneType' object has no attribute 'count'
2020-05-10 16:10:47,332 ERROR: Exception on /login [POST] [in d:\py\microblog\venv\lib\site-packages\flask\app.py:1890]
Traceback (most recent call last):
  File "d:\py\microblog\venv\lib\site-packages\flask\app.py", line 2446, in wsgi_app
    response = self.full_dispatch_request()
  File "d:\py\microblog\venv\lib\site-packages\flask\app.py", line 1951, in full_dispatch_request
    rv = self.handle_user_exception(e)
  File "d:\py\microblog\venv\lib\site-packages\flask\app.py", line 1820, in handle_user_exception
    reraise(exc_type, exc_value, tb)
  File "d:\py\microblog\venv\lib\site-packages\flask\_compat.py", line 39, in reraise
    raise value
  File "d:\py\microblog\venv\lib\site-packages\flask\app.py", line 1949, in full_dispatch_request
    rv = self.dispatch_request()
  File "d:\py\microblog\venv\lib\site-packages\flask\app.py", line 1935, in dispatch_request
    return self.view_functions[rule.endpoint](**req.view_args)
  File "D:\py\microblog\app\routes.py", line 34, in login
    if user is None or not user.check_password(form.password.data):
  File "D:\py\microblog\app\models.py", line 32, in check_password
    return check_password_hash(self.password_hash, password)
  File "d:\py\microblog\venv\lib\site-packages\werkzeug\security.py", line 218, in check_password_hash
    if pwhash.count("$") < 2:
AttributeError: 'NoneType' object has no attribute 'count'
2020-05-10 16:11:20,508 ERROR: Exception on /login [POST] [in d:\py\microblog\venv\lib\site-packages\flask\app.py:1890]
Traceback (most recent call last):
  File "d:\py\microblog\venv\lib\site-packages\flask\app.py", line 2446, in wsgi_app
    response = self.full_dispatch_request()
  File "d:\py\microblog\venv\lib\site-packages\flask\app.py", line 1951, in full_dispatch_request
    rv = self.handle_user_exception(e)
  File "d:\py\microblog\venv\lib\site-packages\flask\app.py", line 1820, in handle_user_exception
    reraise(exc_type, exc_value, tb)
  File "d:\py\microblog\venv\lib\site-packages\flask\_compat.py", line 39, in reraise
    raise value
  File "d:\py\microblog\venv\lib\site-packages\flask\app.py", line 1949, in full_dispatch_request
    rv = self.dispatch_request()
  File "d:\py\microblog\venv\lib\site-packages\flask\app.py", line 1935, in dispatch_request
    return self.view_functions[rule.endpoint](**req.view_args)
  File "D:\py\microblog\app\routes.py", line 34, in login
    if user is None or not user.check_password(form.password.data):
  File "D:\py\microblog\app\models.py", line 32, in check_password
    return check_password_hash(self.password_hash, password)
  File "d:\py\microblog\venv\lib\site-packages\werkzeug\security.py", line 218, in check_password_hash
    if pwhash.count("$") < 2:
AttributeError: 'NoneType' object has no attribute 'count'
2020-05-22 13:42:05,110 INFO: Microblog startup [in D:\py\microblog\app\__init__.py:43]
2020-05-22 14:11:07,083 INFO: Microblog startup [in D:\py\microblog\app\__init__.py:43]
2020-05-22 14:26:53,559 INFO: Microblog startup [in D:\py\microblog\app\__init__.py:43]
2020-05-22 14:30:56,123 INFO: Microblog startup [in D:\py\microblog\app\__init__.py:43]
2020-05-22 14:36:28,839 INFO: Microblog startup [in D:\py\microblog\app\__init__.py:43]
2020-05-22 14:42:49,890 INFO: Microblog startup [in D:\py\microblog\app\__init__.py:43]
2020-05-22 14:42:51,694 ERROR: Exception on /user/Susan [GET] [in d:\py\microblog\venv\lib\site-packages\flask\app.py:1890]
Traceback (most recent call last):
  File "d:\py\microblog\venv\lib\site-packages\flask\app.py", line 2446, in wsgi_app
    response = self.full_dispatch_request()
  File "d:\py\microblog\venv\lib\site-packages\flask\app.py", line 1951, in full_dispatch_request
    rv = self.handle_user_exception(e)
  File "d:\py\microblog\venv\lib\site-packages\flask\app.py", line 1820, in handle_user_exception
    reraise(exc_type, exc_value, tb)
  File "d:\py\microblog\venv\lib\site-packages\flask\_compat.py", line 39, in reraise
    raise value
  File "d:\py\microblog\venv\lib\site-packages\flask\app.py", line 1949, in full_dispatch_request
    rv = self.dispatch_request()
  File "d:\py\microblog\venv\lib\site-packages\flask\app.py", line 1935, in dispatch_request
    return self.view_functions[rule.endpoint](**req.view_args)
  File "d:\py\microblog\venv\lib\site-packages\flask_login\utils.py", line 272, in decorated_view
    return func(*args, **kwargs)
  File "D:\py\microblog\app\routes.py", line 67, in user
    posts = current_user.all()
  File "d:\py\microblog\venv\lib\site-packages\werkzeug\local.py", line 347, in __getattr__
    return getattr(self._get_current_object(), name)
AttributeError: 'User' object has no attribute 'all'
2020-05-22 14:42:52,592 ERROR: Exception on /user/Susan [GET] [in d:\py\microblog\venv\lib\site-packages\flask\app.py:1890]
Traceback (most recent call last):
  File "d:\py\microblog\venv\lib\site-packages\flask\app.py", line 2446, in wsgi_app
    response = self.full_dispatch_request()
  File "d:\py\microblog\venv\lib\site-packages\flask\app.py", line 1951, in full_dispatch_request
    rv = self.handle_user_exception(e)
  File "d:\py\microblog\venv\lib\site-packages\flask\app.py", line 1820, in handle_user_exception
    reraise(exc_type, exc_value, tb)
  File "d:\py\microblog\venv\lib\site-packages\flask\_compat.py", line 39, in reraise
    raise value
  File "d:\py\microblog\venv\lib\site-packages\flask\app.py", line 1949, in full_dispatch_request
    rv = self.dispatch_request()
  File "d:\py\microblog\venv\lib\site-packages\flask\app.py", line 1935, in dispatch_request
    return self.view_functions[rule.endpoint](**req.view_args)
  File "d:\py\microblog\venv\lib\site-packages\flask_login\utils.py", line 272, in decorated_view
    return func(*args, **kwargs)
  File "D:\py\microblog\app\routes.py", line 67, in user
    posts = current_user.all()
  File "d:\py\microblog\venv\lib\site-packages\werkzeug\local.py", line 347, in __getattr__
    return getattr(self._get_current_object(), name)
AttributeError: 'User' object has no attribute 'all'
