2020-05-24 14:31:43,915 ERROR: Exception on /reset_password_request [POST] [in d:\py\microblog\venv\lib\site-packages\flask\app.py:1890]
Traceback (most recent call last):
  File "d:\py\microblog\venv\lib\site-packages\flask_mail.py", line 492, in send
    message.send(connection)
  File "d:\py\microblog\venv\lib\site-packages\flask_mail.py", line 427, in send
    connection.send(self)
  File "d:\py\microblog\venv\lib\site-packages\flask_mail.py", line 188, in send
    self.host.sendmail(sanitize_address(envelope_from or message.sender),
  File "D:\Program Files\Python38\lib\smtplib.py", line 856, in sendmail
    self.ehlo_or_helo_if_needed()
  File "D:\Program Files\Python38\lib\smtplib.py", line 604, in ehlo_or_helo_if_needed
    if not (200 <= self.ehlo()[0] <= 299):
  File "D:\Program Files\Python38\lib\smtplib.py", line 444, in ehlo
    self.putcmd(self.ehlo_msg, name or self.local_hostname)
  File "D:\Program Files\Python38\lib\smtplib.py", line 371, in putcmd
    self.send(str)
  File "D:\Program Files\Python38\lib\smtplib.py", line 363, in send
    raise SMTPServerDisconnected('please run connect() first')
smtplib.SMTPServerDisconnected: please run connect() first

During handling of the above exception, another exception occurred:

Traceback (most recent call last):
  File "d:\py\microblog\venv\lib\site-packages\flask\app.py", line 2446, in wsgi_app
    response = self.full_dispatch_request()
  File "d:\py\microblog\venv\lib\site-packages\flask\app.py", line 1951, in full_dispatch_request
    rv = self.handle_user_exception(e)
  File "d:\py\microblog\venv\lib\site-packages\flask\app.py", line 1820, in handle_user_exception
    reraise(exc_type, exc_value, tb)
  File "d:\py\microblog\venv\lib\site-packages\flask\_compat.py", line 39, in reraise
    raise value
  File "d:\py\microblog\venv\lib\site-packages\flask\app.py", line 1949, in full_dispatch_request
    rv = self.dispatch_request()
  File "d:\py\microblog\venv\lib\site-packages\flask\app.py", line 1935, in dispatch_request
    return self.view_functions[rule.endpoint](**req.view_args)
  File "D:\py\microblog\app\routes.py", line 151, in reset_password_request
    send_password_reset_email(user)
  File "D:\py\microblog\app\email.py", line 13, in send_password_reset_email
    send_email('[Microblog] Reset Your Password',
  File "D:\py\microblog\app\email.py", line 9, in send_email
    mail.send(msg)
  File "d:\py\microblog\venv\lib\site-packages\flask_mail.py", line 492, in send
    message.send(connection)
  File "d:\py\microblog\venv\lib\site-packages\flask_mail.py", line 152, in __exit__
    self.host.quit()
  File "D:\Program Files\Python38\lib\smtplib.py", line 988, in quit
    res = self.docmd("quit")
  File "D:\Program Files\Python38\lib\smtplib.py", line 424, in docmd
    self.putcmd(cmd, args)
  File "D:\Program Files\Python38\lib\smtplib.py", line 371, in putcmd
    self.send(str)
  File "D:\Program Files\Python38\lib\smtplib.py", line 363, in send
    raise SMTPServerDisconnected('please run connect() first')
smtplib.SMTPServerDisconnected: please run connect() first
2020-05-24 14:32:01,894 ERROR: Exception on /reset_password_request [POST] [in d:\py\microblog\venv\lib\site-packages\flask\app.py:1890]
Traceback (most recent call last):
  File "d:\py\microblog\venv\lib\site-packages\flask_mail.py", line 492, in send
    message.send(connection)
  File "d:\py\microblog\venv\lib\site-packages\flask_mail.py", line 427, in send
    connection.send(self)
  File "d:\py\microblog\venv\lib\site-packages\flask_mail.py", line 188, in send
    self.host.sendmail(sanitize_address(envelope_from or message.sender),
  File "D:\Program Files\Python38\lib\smtplib.py", line 856, in sendmail
    self.ehlo_or_helo_if_needed()
  File "D:\Program Files\Python38\lib\smtplib.py", line 604, in ehlo_or_helo_if_needed
    if not (200 <= self.ehlo()[0] <= 299):
  File "D:\Program Files\Python38\lib\smtplib.py", line 444, in ehlo
    self.putcmd(self.ehlo_msg, name or self.local_hostname)
  File "D:\Program Files\Python38\lib\smtplib.py", line 371, in putcmd
    self.send(str)
  File "D:\Program Files\Python38\lib\smtplib.py", line 363, in send
    raise SMTPServerDisconnected('please run connect() first')
smtplib.SMTPServerDisconnected: please run connect() first

During handling of the above exception, another exception occurred:

Traceback (most recent call last):
  File "d:\py\microblog\venv\lib\site-packages\flask\app.py", line 2446, in wsgi_app
    response = self.full_dispatch_request()
  File "d:\py\microblog\venv\lib\site-packages\flask\app.py", line 1951, in full_dispatch_request
    rv = self.handle_user_exception(e)
  File "d:\py\microblog\venv\lib\site-packages\flask\app.py", line 1820, in handle_user_exception
    reraise(exc_type, exc_value, tb)
  File "d:\py\microblog\venv\lib\site-packages\flask\_compat.py", line 39, in reraise
    raise value
  File "d:\py\microblog\venv\lib\site-packages\flask\app.py", line 1949, in full_dispatch_request
    rv = self.dispatch_request()
  File "d:\py\microblog\venv\lib\site-packages\flask\app.py", line 1935, in dispatch_request
    return self.view_functions[rule.endpoint](**req.view_args)
  File "D:\py\microblog\app\routes.py", line 151, in reset_password_request
    send_password_reset_email(user)
  File "D:\py\microblog\app\email.py", line 13, in send_password_reset_email
    send_email('[Microblog] Reset Your Password',
  File "D:\py\microblog\app\email.py", line 9, in send_email
    mail.send(msg)
  File "d:\py\microblog\venv\lib\site-packages\flask_mail.py", line 492, in send
    message.send(connection)
  File "d:\py\microblog\venv\lib\site-packages\flask_mail.py", line 152, in __exit__
    self.host.quit()
  File "D:\Program Files\Python38\lib\smtplib.py", line 988, in quit
    res = self.docmd("quit")
  File "D:\Program Files\Python38\lib\smtplib.py", line 424, in docmd
    self.putcmd(cmd, args)
  File "D:\Program Files\Python38\lib\smtplib.py", line 371, in putcmd
    self.send(str)
  File "D:\Program Files\Python38\lib\smtplib.py", line 363, in send
    raise SMTPServerDisconnected('please run connect() first')
smtplib.SMTPServerDisconnected: please run connect() first
2020-05-26 12:52:22,633 INFO: Microblog startup [in D:\py\microblog\app\__init__.py:49]
2020-05-26 12:53:38,526 ERROR: Exception on /user/Alex [GET] [in d:\py\microblog\venv\lib\site-packages\flask\app.py:1890]
Traceback (most recent call last):
  File "d:\py\microblog\venv\lib\site-packages\flask\app.py", line 2446, in wsgi_app
    response = self.full_dispatch_request()
  File "d:\py\microblog\venv\lib\site-packages\flask\app.py", line 1951, in full_dispatch_request
    rv = self.handle_user_exception(e)
  File "d:\py\microblog\venv\lib\site-packages\flask\app.py", line 1820, in handle_user_exception
    reraise(exc_type, exc_value, tb)
  File "d:\py\microblog\venv\lib\site-packages\flask\_compat.py", line 39, in reraise
    raise value
  File "d:\py\microblog\venv\lib\site-packages\flask\app.py", line 1949, in full_dispatch_request
    rv = self.dispatch_request()
  File "d:\py\microblog\venv\lib\site-packages\flask\app.py", line 1935, in dispatch_request
    return self.view_functions[rule.endpoint](**req.view_args)
  File "d:\py\microblog\venv\lib\site-packages\flask_login\utils.py", line 272, in decorated_view
    return func(*args, **kwargs)
  File "D:\py\microblog\app\routes.py", line 89, in user
    return render_template('user.html', user=user, posts=posts.items,
  File "d:\py\microblog\venv\lib\site-packages\flask\templating.py", line 137, in render_template
    return _render(
  File "d:\py\microblog\venv\lib\site-packages\flask\templating.py", line 120, in _render
    rv = template.render(context)
  File "d:\py\microblog\venv\lib\site-packages\jinja2\environment.py", line 1090, in render
    self.environment.handle_exception()
  File "d:\py\microblog\venv\lib\site-packages\jinja2\environment.py", line 832, in handle_exception
    reraise(*rewrite_traceback_stack(source=source))
  File "d:\py\microblog\venv\lib\site-packages\jinja2\_compat.py", line 28, in reraise
    raise value.with_traceback(tb)
  File "D:\py\microblog\app\templates\user.html", line 1, in top-level template code
    {% extends "base.html" %}
  File "D:\py\microblog\app\templates\base.html", line 1, in top-level template code
    {% extends 'bootstrap/base.html' %}
  File "d:\py\microblog\venv\lib\site-packages\flask_bootstrap\templates\bootstrap\base.html", line 1, in top-level template code
    {% block doc -%}
  File "d:\py\microblog\venv\lib\site-packages\flask_bootstrap\templates\bootstrap\base.html", line 3, in block "doc"
    <html{% block html_attribs %}{% endblock html_attribs %}>
  File "d:\py\microblog\venv\lib\site-packages\flask_bootstrap\templates\bootstrap\base.html", line 11, in block "html"
    {%- endblock metas %}
  File "d:\py\microblog\venv\lib\site-packages\flask_bootstrap\templates\bootstrap\base.html", line 13, in block "body"
    {%- block styles %}
  File "D:\py\microblog\app\templates\base.html", line 48, in block "content"
    {% block app_content %}{% endblock %}
  File "D:\py\microblog\app\templates\user.html", line 17, in block "app_content"
    {{ form.hidden_tag() }}
  File "d:\py\microblog\venv\lib\site-packages\jinja2\environment.py", line 471, in getattr
    return getattr(obj, attribute)
jinja2.exceptions.UndefinedError: 'form' is undefined
