2020-05-22 15:10:03,223 ERROR: Exception on /user/Susan [GET] [in d:\py\microblog\venv\lib\site-packages\flask\app.py:1890]
Traceback (most recent call last):
  File "d:\py\microblog\venv\lib\site-packages\flask\app.py", line 2446, in wsgi_app
    response = self.full_dispatch_request()
  File "d:\py\microblog\venv\lib\site-packages\flask\app.py", line 1951, in full_dispatch_request
    rv = self.handle_user_exception(e)
  File "d:\py\microblog\venv\lib\site-packages\flask\app.py", line 1820, in handle_user_exception
    reraise(exc_type, exc_value, tb)
  File "d:\py\microblog\venv\lib\site-packages\flask\_compat.py", line 39, in reraise
    raise value
  File "d:\py\microblog\venv\lib\site-packages\flask\app.py", line 1949, in full_dispatch_request
    rv = self.dispatch_request()
  File "d:\py\microblog\venv\lib\site-packages\flask\app.py", line 1935, in dispatch_request
    return self.view_functions[rule.endpoint](**req.view_args)
  File "d:\py\microblog\venv\lib\site-packages\flask_login\utils.py", line 272, in decorated_view
    return func(*args, **kwargs)
  File "D:\py\microblog\app\routes.py", line 70, in user
    posts = Post.query.filter_by(user_id=self.id)
NameError: name 'self' is not defined
2020-05-22 15:10:04,154 ERROR: Exception on /user/Susan [GET] [in d:\py\microblog\venv\lib\site-packages\flask\app.py:1890]
Traceback (most recent call last):
  File "d:\py\microblog\venv\lib\site-packages\flask\app.py", line 2446, in wsgi_app
    response = self.full_dispatch_request()
  File "d:\py\microblog\venv\lib\site-packages\flask\app.py", line 1951, in full_dispatch_request
    rv = self.handle_user_exception(e)
  File "d:\py\microblog\venv\lib\site-packages\flask\app.py", line 1820, in handle_user_exception
    reraise(exc_type, exc_value, tb)
  File "d:\py\microblog\venv\lib\site-packages\flask\_compat.py", line 39, in reraise
    raise value
  File "d:\py\microblog\venv\lib\site-packages\flask\app.py", line 1949, in full_dispatch_request
    rv = self.dispatch_request()
  File "d:\py\microblog\venv\lib\site-packages\flask\app.py", line 1935, in dispatch_request
    return self.view_functions[rule.endpoint](**req.view_args)
  File "d:\py\microblog\venv\lib\site-packages\flask_login\utils.py", line 272, in decorated_view
    return func(*args, **kwargs)
  File "D:\py\microblog\app\routes.py", line 70, in user
    posts = Post.query.filter_by(user_id=self.id)
NameError: name 'self' is not defined
2020-05-22 15:10:04,696 ERROR: Exception on /user/Susan [GET] [in d:\py\microblog\venv\lib\site-packages\flask\app.py:1890]
Traceback (most recent call last):
  File "d:\py\microblog\venv\lib\site-packages\flask\app.py", line 2446, in wsgi_app
    response = self.full_dispatch_request()
  File "d:\py\microblog\venv\lib\site-packages\flask\app.py", line 1951, in full_dispatch_request
    rv = self.handle_user_exception(e)
  File "d:\py\microblog\venv\lib\site-packages\flask\app.py", line 1820, in handle_user_exception
    reraise(exc_type, exc_value, tb)
  File "d:\py\microblog\venv\lib\site-packages\flask\_compat.py", line 39, in reraise
    raise value
  File "d:\py\microblog\venv\lib\site-packages\flask\app.py", line 1949, in full_dispatch_request
    rv = self.dispatch_request()
  File "d:\py\microblog\venv\lib\site-packages\flask\app.py", line 1935, in dispatch_request
    return self.view_functions[rule.endpoint](**req.view_args)
  File "d:\py\microblog\venv\lib\site-packages\flask_login\utils.py", line 272, in decorated_view
    return func(*args, **kwargs)
  File "D:\py\microblog\app\routes.py", line 70, in user
    posts = Post.query.filter_by(user_id=self.id)
NameError: name 'self' is not defined
2020-05-22 15:10:05,326 ERROR: Exception on /user/Susan [GET] [in d:\py\microblog\venv\lib\site-packages\flask\app.py:1890]
Traceback (most recent call last):
  File "d:\py\microblog\venv\lib\site-packages\flask\app.py", line 2446, in wsgi_app
    response = self.full_dispatch_request()
  File "d:\py\microblog\venv\lib\site-packages\flask\app.py", line 1951, in full_dispatch_request
    rv = self.handle_user_exception(e)
  File "d:\py\microblog\venv\lib\site-packages\flask\app.py", line 1820, in handle_user_exception
    reraise(exc_type, exc_value, tb)
  File "d:\py\microblog\venv\lib\site-packages\flask\_compat.py", line 39, in reraise
    raise value
  File "d:\py\microblog\venv\lib\site-packages\flask\app.py", line 1949, in full_dispatch_request
    rv = self.dispatch_request()
  File "d:\py\microblog\venv\lib\site-packages\flask\app.py", line 1935, in dispatch_request
    return self.view_functions[rule.endpoint](**req.view_args)
  File "d:\py\microblog\venv\lib\site-packages\flask_login\utils.py", line 272, in decorated_view
    return func(*args, **kwargs)
  File "D:\py\microblog\app\routes.py", line 70, in user
    posts = Post.query.filter_by(user_id=self.id)
NameError: name 'self' is not defined
2020-05-22 15:10:12,650 ERROR: Exception on /user/Susan [GET] [in d:\py\microblog\venv\lib\site-packages\flask\app.py:1890]
Traceback (most recent call last):
  File "d:\py\microblog\venv\lib\site-packages\flask\app.py", line 2446, in wsgi_app
    response = self.full_dispatch_request()
  File "d:\py\microblog\venv\lib\site-packages\flask\app.py", line 1951, in full_dispatch_request
    rv = self.handle_user_exception(e)
  File "d:\py\microblog\venv\lib\site-packages\flask\app.py", line 1820, in handle_user_exception
    reraise(exc_type, exc_value, tb)
  File "d:\py\microblog\venv\lib\site-packages\flask\_compat.py", line 39, in reraise
    raise value
  File "d:\py\microblog\venv\lib\site-packages\flask\app.py", line 1949, in full_dispatch_request
    rv = self.dispatch_request()
  File "d:\py\microblog\venv\lib\site-packages\flask\app.py", line 1935, in dispatch_request
    return self.view_functions[rule.endpoint](**req.view_args)
  File "d:\py\microblog\venv\lib\site-packages\flask_login\utils.py", line 272, in decorated_view
    return func(*args, **kwargs)
  File "D:\py\microblog\app\routes.py", line 70, in user
    posts = Post.query.filter_by(user_id=self.id)
NameError: name 'self' is not defined
2020-05-22 15:10:18,972 ERROR: Exception on /user/Susan [GET] [in d:\py\microblog\venv\lib\site-packages\flask\app.py:1890]
Traceback (most recent call last):
  File "d:\py\microblog\venv\lib\site-packages\flask\app.py", line 2446, in wsgi_app
    response = self.full_dispatch_request()
  File "d:\py\microblog\venv\lib\site-packages\flask\app.py", line 1951, in full_dispatch_request
    rv = self.handle_user_exception(e)
  File "d:\py\microblog\venv\lib\site-packages\flask\app.py", line 1820, in handle_user_exception
    reraise(exc_type, exc_value, tb)
  File "d:\py\microblog\venv\lib\site-packages\flask\_compat.py", line 39, in reraise
    raise value
  File "d:\py\microblog\venv\lib\site-packages\flask\app.py", line 1949, in full_dispatch_request
    rv = self.dispatch_request()
  File "d:\py\microblog\venv\lib\site-packages\flask\app.py", line 1935, in dispatch_request
    return self.view_functions[rule.endpoint](**req.view_args)
  File "d:\py\microblog\venv\lib\site-packages\flask_login\utils.py", line 272, in decorated_view
    return func(*args, **kwargs)
  File "D:\py\microblog\app\routes.py", line 70, in user
    posts = Post.query.filter_by(user_id=self.id)
NameError: name 'self' is not defined
2020-05-22 15:18:05,358 INFO: Microblog startup [in D:\py\microblog\app\__init__.py:43]
2020-05-22 15:21:24,663 INFO: Microblog startup [in D:\py\microblog\app\__init__.py:43]
2020-05-22 15:25:34,941 INFO: Microblog startup [in D:\py\microblog\app\__init__.py:43]
2020-05-22 15:27:18,767 INFO: Microblog startup [in D:\py\microblog\app\__init__.py:43]
2020-05-22 15:29:32,298 INFO: Microblog startup [in D:\py\microblog\app\__init__.py:43]
2020-05-24 11:56:58,687 INFO: Microblog startup [in D:\py\microblog\app\__init__.py:43]
2020-05-24 12:05:31,291 INFO: Microblog startup [in D:\py\microblog\app\__init__.py:43]
2020-05-24 12:06:36,839 INFO: Microblog startup [in D:\py\microblog\app\__init__.py:43]
2020-05-24 12:10:05,823 INFO: Microblog startup [in D:\py\microblog\app\__init__.py:43]
2020-05-24 12:29:45,424 INFO: Microblog startup [in D:\py\microblog\app\__init__.py:43]
2020-05-24 12:47:02,014 INFO: Microblog startup [in D:\py\microblog\app\__init__.py:45]
2020-05-24 12:55:56,732 INFO: Microblog startup [in D:\py\microblog\app\__init__.py:45]
2020-05-24 13:04:24,662 INFO: Microblog startup [in D:\py\microblog\app\__init__.py:45]
2020-05-24 13:06:51,691 INFO: Microblog startup [in D:\py\microblog\app\__init__.py:45]
2020-05-24 13:48:19,347 INFO: Microblog startup [in D:\py\microblog\app\__init__.py:45]
2020-05-24 14:20:21,112 INFO: Microblog startup [in D:\py\microblog\app\__init__.py:45]
2020-05-24 14:25:20,623 INFO: Microblog startup [in D:\py\microblog\app\__init__.py:45]
2020-05-24 14:30:15,952 INFO: Microblog startup [in D:\py\microblog\app\__init__.py:45]
